Workbook

Sheet GLOBAL
A1: DATE | B1: ARTICLE | C1: QUANTITE | D1: UNITE | E1: PRIX UNITAIRE | F1: MONTANT TOTAL HT | G1: TVA 19% | H1: TOTAL TTC | I1: FOURNISSEUR | J1: PROJET | K1: N FACTURE | L1: NUM CHEQUE
A2: 45668 | B2: CHAUSSURE S26 | C2: 1 | D2: U | E2: 3100 | F2: =C2*E2 -> 3100 | G2: =F2*0.19 -> 589 | H2: =F2+G2 -> 3689 | I2: GR SAF PROTECT | J2: VIEUX KOUBA | K2: 832/2026 | L2: 4065491
A3: 45668 | B3: BLIE TRAVAIL NEO | C3: 3 | D3: U | E3: 2900 | F3: =C3*E3 -> 8700 | G3: =F3*0.19 -> 1653 | H3: =F3+G3 -> 10353 | I3: GR SAF PROTECT | J3: VIEUX KOUBA | K3: 832/2026 | L3: 4065491
A4: 45668 | B4: BLUE TRAVAIL POWER BLUE | C4: 5 | D4: U | E4: 2300 | F4: =C4*E4 -> 11500 | G4: =F4*0.19 -> 2185 | H4: =F4+G4 -> 13685 | I4: GR SAF PROTECT | J4: VIEUX KOUBA | K4: 832/2026 | L4: 4065491
A5: 45668 | B5: BLUE TRAVAIL CROWN | C5: 1 | D5: U | E5: 3800 | F5: =C5*E5 -> 3800 | G5: =F5*0.19 -> 722 | H5: =F5+G5 -> 4522 | I5: GR SAF PROTECT | J5: VIEUX KOUBA | K5: 832/2026 | L5: 4065491
A6: 45668 | B6: GILET JAUNE BORDURE | C6: 12 | D6: U | E6: 750 | F6: =C6*E6 -> 9000 | G6: =F6*0.19 -> 1710 | H6: =F6+G6 -> 10710 | I6: GR SAF PROTECT | J6: VIEUX KOUBA | K6: 832/2026 | L6: 4065491
A7: 45668 | B7: CHAUSSURE NAIKI S3 | C7: 13 | D7: U | E7: 3100 | F7: =C7*E7 -> 40300 | G7: =F7*0.19 -> 7657 | H7: =F7+G7 -> 47957 | I7: GR SAF PROTECT | J7: VIEUX KOUBA | K7: 832/2026 | L7: 4065491
A8: 45668 | B8: FOURNITURE ET POSE SE BATIS SUPPORT | C8: 50 | D8: U | E8: 23361.35 | F8: =C8*E8 -> 1168067.5 | G8: =F8*0.19 -> 221932.83 | H8: =F8+G8 -> 1390000.3 | I8: SARL OCTOGONIA | J8: VIEUX KOUBA | K8: 26112026-0501-001 | L8: 4065460
A9: 45929 | B9: GANT BARBE VERT PISTACHE/BLUE NOIR RABILOTA | C9: 24 | D9: U | E9: 115 | F9: =C9*E9 -> 2760 | G9: =F9*0.19 -> 524.4 | H9: =F9+G9 -> 3284.4 | I9: SNC MASSOUMA DOUDOU ET CIE | J9: VIEUX KOUBA | K9: 00175/2025 | L9: 4065495
A10: 45929 | B10: MASQUE POUSSIERE BLANC VAST KN95 SAC 5PCS | C10: 20 | D10: U | E10: 68 | F10: =C10*E10 -> 1360 | G10: =F10*0.19 -> 258.4 | H10: =F10+G10 -> 1618.4 | I10: SNC MASSOUMA DOUDOU ET CIE | J10: VIEUX KOUBA | K10: 00175/2025 | L10: 4065495
A11: 45929 | B11: LUNETTE DE SABLE TRANSPARENT ELASTIQUE | C11: 20 | D11: U | E11: 127 | F11: =C11*E11 -> 2540 | G11: =F11*0.19 -> 482.6 | H11: =F11+G11 -> 3022.6 | I11: SNC MASSOUMA DOUDOU ET CIE | J11: VIEUX KOUBA | K11: 00175/2025 | L11: 4065495
A12: 45929 | B12: BOMBE PEINTURE ROUGE ALLAL | C12: 12 | D12: U | E12: 345 | F12: =C12*E12 -> 4140 | G12: =F12*0.19 -> 786.6 | H12: =F12+G12 -> 4926.6 | I12: SNC MASSOUMA DOUDOU ET CIE | J12: VIEUX KOUBA | K12: 00175/2025 | L12: 4065495
A13: 45929 | B13: CRAION MACON PLAT 12 PS MINGLI TISON LAMBOSS | C13: 1 | D13: U | E13: 343 | F13: =C13*E13 -> 343 | G13: =F13*0.19 -> 65.17 | H13: =F13+G13 -> 408.17 | I13: SNC MASSOUMA DOUDOU ET CIE | J13: VIEUX KOUBA | K13: 00175/2025 | L13: 4065495
... A42: 45965 | B42: INTERFACE USB/KNX | C42: 1 | D42: U | E42: 21176.47 | F42: =C42*E42 -> 21176.47 | G42: =F42*0.19 -> 4023.5293 | H42: =F42+G42 -> 25199.999 | I42: CEFA | J42: VIEUX KOUBA | K42: 00071/2026 | L42: 3165209
A43: 46054 | B43: DISTRIBUTEUR 5 VOIES D 16 1"-26/34 A VISSER | C43: 2 | D43: U | E43: 5411.67 | F43: =C43*E43 -> 10823.34 | G43: =F43*0.19 -> 2056.4346 | H43: =F43+G43 -> 12879.775 | I43: BENROKHROCH ABDESSAMAD ETS AGUATECH | J43: VIEUX KOUBA | K43: 0153/2026 | L43: OD
A44: 46054 | B44: DISTRIBUTEUR 6 VOIES D 16 1"-26/34 A VISSER | C44: 8 | D44: U | E44: 6454.04 | F44: =C44*E44 -> 51632.32 | G44: =F44*0.19 -> 9810.1408 | H44: =F44+G44 -> 61442.461 | I44: BENROKHROCH ABDESSAMAD ETS AGUATECH | J44: VIEUX KOUBA | K44: 0153/2026 | L44: OD
A45: 46054 | B45: DISTRIBUTEUR 6 VOIES D 16 3/4"-20/27 A VISSER | C45: 14 | D45: U | E45: 5777.31 | F45: =C45*E45 -> 80882.34 | G45: =F45*0.19 -> 15367.645 | H45: =F45+G45 -> 96249.985 | I45: BENROKHROCH ABDESSAMAD ETS AGUATECH | J45: VIEUX KOUBA | K45: 0153/2026 | L45: OD
A46: 46054 | B46: DISTRIBUTEUR 5 VOIES D 16 3/4"-20/27 A VISSER | C46: 7 | D46: U | E46: 4529.41 | F46: =C46*E46 -> 31705.87 | G46: =F46*0.19 -> 6024.1153 | H46: =F46+G46 -> 37729.985 | I46: BENROKHROCH ABDESSAMAD ETS AGUATECH | J46: VIEUX KOUBA | K46: 0153/2026 | L46: OD
A47: 46054 | B47: DISTRIBUTEUR 4 VOIES D 16 3/4"-20/27 A VISSER | C47: 15 | D47: U | E47: 3836.13 | F47: =C47*E47 -> 57541.95 | G47: =F47*0.19 -> 10932.971 | H47: =F47+G47 -> 68474.921 | I47: BENROKHROCH ABDESSAMAD ETS AGUATECH | J47: VIEUX KOUBA | K47: 0153/2026 | L47: OD
A48: 46054 | B48: DISTRIBUTEUR 3 VOIES D 16 3/4"-20/27 A VISSER | C48: 11 | D48: U | E48: 2897.89 | F48: =C48*E48 -> 31876.79 | G48: =F48*0.19 -> 6056.5901 | H48: =F48+G48 -> 37933.38 | I48: BENROKHROCH ABDESSAMAD ETS AGUATECH | J48: VIEUX KOUBA | K48: 0153/2026 | L48: OD
A49: 46054 | B49: TUBE MC PEX /AL/PEX ALIMENTAIRE D 16 CALORIFUGE BLUE | C49: 2000 | D49: U | E49: 155.29 | F49: =C49*E49 -> 310580 | G49: =F49*0.19 -> 59010.2 | H49: =F49+G49 -> 369590.2 | I49: BENROKHROCH ABDESSAMAD ETS AGUATECH | J49: VIEUX KOUBA | K49: 0153/2026 | L49: OD
A50: 46054 | B50: TUBE MC PEX /AL/PEX ALIMENTAIRE D 16 CALORIFUGE ROUGE | C50: 2000 | D50: U | E50: 155.29 | F50: =C50*E50 -> 310580 | G50: =F50*0.19 -> 59010.2 | H50: =F50+G50 -> 369590.2 | I50: BENROKHROCH ABDESSAMAD ETS AGUATECH | J50: VIEUX KOUBA | K50: 0153/2026 | L50: OD
A51: 46054 | B51: TUBE MC CHILAI PEX D 16 GAINE BLUE | C51: 2000 | D51: U | E51: 103.52 | F51: =C51*E51 -> 207040 | G51: =F51*0.19 -> 39337.6 | H51: =F51+G51 -> 246377.6 | I51: BENROKHROCH ABDESSAMAD ETS AGUATECH | J51: VIEUX KOUBA | K51: 0153/2026 | L51: OD
A52: 46054 | B52: TUBE MC CHILAI PEX D 16 GAINE ROUGE | C52: 1000 | D52: U | E52: 103.52 | F52: =C52*E52 -> 103520 | G52: =F52*0.19 -> 19668.8 | H52: =F52+G52 -> 123188.8 | I52: BENROKHROCH ABDESSAMAD ETS AGUATECH | J52: VIEUX KOUBA | K52: 0153/2026 | L52: OD
A53: 46054 | B53: TUBE SIMPLE D 32 PN-20 PPRC | C53: 250 | D53: U | E53: 162.98 | F53: =C53*E53 -> 40745 | G53: =F53*0.19 -> 7741.55 | H53: =F53+G53 -> 48486.55 | I53: BENROKHROCH ABDESSAMAD ETS AGUATECH | J53: VIEUX KOUBA | K53: 0153/2026 | L53: OD
A54: 46054 | B54: COUDE 90° D32 PPRC | C54: 100 | D54: U | E54: 25.16 | F54: =C54*E54 -> 2516 | G54: =F54*0.19 -> 478.04 | H54: =F54+G54 -> 2994.04 | I54: BENROKHROCH ABDESSAMAD ETS AGUATECH | J54: VIEUX KOUBA | K54: 0153/2026 | L54: OD
... A78: 46054 | B78: TEFLON LIQUIDE BLEU 50 ML | C78: 8 | D78: U | E78: 554.62 | F78: =C78*E78 -> 4436.96 | G78: =F78*0.19 -> 843.0224 | H78: =F78+G78 -> 5279.9824 | I78: BENROKHROCH ABDESSAMAD ETS AGUATECH | J78: VIEUX KOUBA | K78: 0153/2026 | L78: OD
A79: 46041 | B79: SIKA WALL 10 PRIMER PL20 | C79: 20 | D79: PCS | E79: 4201.68 | F79: =C79*E79 -> 84033.6 | G79: =F79*0.19 -> 15966.384 | H79: =F79+G79 -> 99999.984 | I79: BACHA FARID | J79: VIEUX KOUBA | K79: 0024/2026 | L79: 4065452
A80: 46041 | B80: POINTE DE PARIS 100 | C80: 10 | D80: KG | E80: 159.66 | F80: =C80*E80 -> 1596.6 | G80: =F80*0.19 -> 303.354 | H80: =F80+G80 -> 1899.954 | I80: BACHA FARID | J80: VIEUX KOUBA | K80: 0024/2026 | L80: 4065452
A81: 46043 | B81: SDS PLUS P4/8*210 MM | C81: 20 | D81: U | E81: 1325.22 | F81: =C81*E81 -> 26504.4 | G81: =F81*0.19 -> 5035.836 | H81: =F81+G81 -> 31540.236 | I81: EURL HADDAD EQUIPMENT PROFFESIONNEL | J81: VIEUX KOUBA | K81: 00025/2026 | L81: 4065468
A82: 46043 | B82: SDS PLUS P4/8*210 MM | C82: 10 | D82: U | E82: 1562.93 | F82: =C82*E82 -> 15629.3 | G82: =F82*0.19 -> 2969.567 | H82: =F82+G82 -> 18598.867 | I82: EURL HADDAD EQUIPMENT PROFFESIONNEL | J82: VIEUX KOUBA | K82: 00025/2026 | L82: 4065468
A83: 46043 | B83: SDS PLUS P4/8*210 MM | C83: 10 | D83: U | E83: 1877.16 | F83: =C83*E83 -> 18771.6 | G83: =F83*0.19 -> 3566.604 | H83: =F83+G83 -> 22338.204 | I83: EURL HADDAD EQUIPMENT PROFFESIONNEL | J83: VIEUX KOUBA | K83: 00025/2026 | L83: 4065468
A84: 46043 | B84: SDS FORET MARTEAU 14*200 MM | C84: 10 | D84: U | E84: 1540.15 | F84: =C84*E84 -> 15401.5 | G84: =F84*0.19 -> 2926.285 | H84: =F84+G84 -> 18327.785 | I84: EURL HADDAD EQUIPMENT PROFFESIONNEL | J84: VIEUX KOUBA | K84: 00025/2026 | L84: 4065468
A85: 46048 | B85: TUBE PVC D 125 PNO6 COLLER EP3,2 | C85: 90 | D85: U | E85: 477.6 | F85: =C85*E85 -> 42984 | G85: =F85*0.19 -> 8166.96 | H85: =F85+G85 -> 51150.96 | I85: BENROKHROCH ABDESSAMAD ETS AGUATECH | J85: VIEUX KOUBA | K85: 0102/2026 | L85: OD
A86: 46048 | B86: Y REDUIT PVC D110*50 | C86: 22 | D86: U | E86: 172.85 | F86: =C86*E86 -> 3802.7 | G86: =F86*0.19 -> 722.513 | H86: =F86+G86 -> 4525.213 | I86: BENROKHROCH ABDESSAMAD ETS AGUATECH | J86: VIEUX KOUBA | K86: 0102/2026 | L86: OD
A87: 46048 | B87: Y REDUIT PVC D110*40 | C87: 120 | D87: U | E87: 162.68 | F87: =C87*E87 -> 19521.6 | G87: =F87*0.19 -> 3709.104 | H87: =F87+G87 -> 23230.704 | I87: BENROKHROCH ABDESSAMAD ETS AGUATECH | J87: VIEUX KOUBA | K87: 0102/2026 | L87: OD
A88: 46048 | B88: Y REDUIT PVC D80*40 | C88: 12 | D88: U | E88: 121.09 | F88: =C88*E88 -> 1453.08 | G88: =F88*0.19 -> 276.0852 | H88: =F88+G88 -> 1729.1652 | I88: BENROKHROCH ABDESSAMAD ETS AGUATECH | J88: VIEUX KOUBA | K88: 0102/2026 | L88: OD
A89: 46048 | B89: Y REDUIT PVC D110 | C89: 12 | D89: U | E89: 233.86 | F89: =C89*E89 -> 2806.32 | G89: =F89*0.19 -> 533.2008 | H89: =F89+G89 -> 3339.5208 | I89: BENROKHROCH ABDESSAMAD ETS AGUATECH | J89: VIEUX KOUBA | K89: 0102/2026 | L89: OD
A90: 46048 | B90: CHEVILLE PLASTIAUE N10 | C90: 600 | D90: U | E90: 2.77 | F90: =C90*E90 -> 1662 | G90: =F90*0.19 -> 315.78 | H90: =F90+G90 -> 1977.78 | I90: BENROKHROCH ABDESSAMAD ETS AGUATECH | J90: VIEUX KOUBA | K90: 0102/2026 | L90: OD
A91: 46048 | B91: TUBE PVC D10 PN06 A COLLER EP 2,0 | C91: 444 | D91: U | E91: 344.53 | F91: =C91*E91 -> 152971.32 | G91: =F91*0.19 -> 29064.551 | H91: =F91+G91 -> 182035.87 | I91: BENROKHROCH ABDESSAMAD ETS AGUATECH | J91: VIEUX KOUBA | K91: 0102/2026 | L91: OD
...

Sheet VIEUX KOUBA
A1: DATE | B1: ARTICLE | C1: QUANTITE | D1: UNITE | E1: PRIX UNITAIRE | F1: MONTANT TOTAL HT | G1: TVA 19% | H1: TOTAL TTC | I1: FOURNISSEUR | J1: PROJET | K1: N FACTURE | L1: NUM CHEQUE
A2: 45668 | B2: CHAUSSURE S26 | C2: 1 | D2: U | E2: 3100 | F2: =C2*E2 -> 3100 | G2: =F2*0.19 -> 589 | H2: =F2+G2 -> 3689 | I2: GR SAF PROTECT | J2: VIEUX KOUBA | K2: 832/2026 | L2: 4065491
A3: 45668 | B3: BLIE TRAVAIL NEO | C3: 3 | D3: U | E3: 2900 | F3: =C3*E3 -> 8700 | G3: =F3*0.19 -> 1653 | H3: =F3+G3 -> 10353 | I3: GR SAF PROTECT | J3: VIEUX KOUBA | K3: 832/2026 | L3: 4065491
A4: 45668 | B4: BLUE TRAVAIL POWER BLUE | C4: 5 | D4: U | E4: 2300 | F4: =C4*E4 -> 11500 | G4: =F4*0.19 -> 2185 | H4: =F4+G4 -> 13685 | I4: GR SAF PROTECT | J4: VIEUX KOUBA | K4: 832/2026 | L4: 4065491
A5: 45668 | B5: BLUE TRAVAIL CROWN | C5: 1 | D5: U | E5: 3800 | F5: =C5*E5 -> 3800 | G5: =F5*0.19 -> 722 | H5: =F5+G5 -> 4522 | I5: GR SAF PROTECT | J5: VIEUX KOUBA | K5: 832/2026 | L5: 4065491
A6: 45668 | B6: GILET JAUNE BORDURE | C6: 12 | D6: U | E6: 750 | F6: =C6*E6 -> 9000 | G6: =F6*0.19 -> 1710 | H6: =F6+G6 -> 10710 | I6: GR SAF PROTECT | J6: VIEUX KOUBA | K6: 832/2026 | L6: 4065491
A7: 45668 | B7: CHAUSSURE NAIKI S3 | C7: 13 | D7: U | E7: 3100 | F7: =C7*E7 -> 40300 | G7: =F7*0.19 -> 7657 | H7: =F7+G7 -> 47957 | I7: GR SAF PROTECT | J7: VIEUX KOUBA | K7: 832/2026 | L7: 4065491
A8: 45668 | B8: FOURNITURE ET POSE SE BATIS SUPPORT | C8: 50 | D8: U | E8: 23361.35 | F8: =C8*E8 -> 1168067.5 | G8: =F8*0.19 -> 221932.83 | H8: =F8+G8 -> 1390000.3 | I8: SARL OCTOGONIA | J8: VIEUX KOUBA | K8: 26112026-0501-001 | L8: 4065460
A9: 45929 | B9: GANT BARBE VERT PISTACHE/BLUE NOIR RABILOTA | C9: 24 | D9: U | E9: 115 | F9: =C9*E9 -> 2760 | G9: =F9*0.19 -> 524.4 | H9: =F9+G9 -> 3284.4 | I9: SNC MASSOUMA DOUDOU ET CIE | J9: VIEUX KOUBA | K9: 00175/2025 | L9: 4065495
A10: 45929 | B10: MASQUE POUSSIERE BLANC VAST KN95 SAC 5PCS | C10: 20 | D10: U | E10: 68 | F10: =C10*E10 -> 1360 | G10: =F10*0.19 -> 258.4 | H10: =F10+G10 -> 1618.4 | I10: SNC MASSOUMA DOUDOU ET CIE | J10: VIEUX KOUBA | K10: 00175/2025 | L10: 4065495
A11: 45929 | B11: LUNETTE DE SABLE TRANSPARENT ELASTIQUE | C11: 20 | D11: U | E11: 127 | F11: =C11*E11 -> 2540 | G11: =F11*0.19 -> 482.6 | H11: =F11+G11 -> 3022.6 | I11: SNC MASSOUMA DOUDOU ET CIE | J11: VIEUX KOUBA | K11: 00175/2025 | L11: 4065495
A12: 45929 | B12: BOMBE PEINTURE ROUGE ALLAL | C12: 12 | D12: U | E12: 345 | F12: =C12*E12 -> 4140 | G12: =F12*0.19 -> 786.6 | H12: =F12+G12 -> 4926.6 | I12: SNC MASSOUMA DOUDOU ET CIE | J12: VIEUX KOUBA | K12: 00175/2025 | L12: 4065495
A13: 45929 | B13: CRAION MACON PLAT 12 PS MINGLI TISON LAMBOSS | C13: 1 | D13: U | E13: 343 | F13: =C13*E13 -> 343 | G13: =F13*0.19 -> 65.17 | H13: =F13+G13 -> 408.17 | I13: SNC MASSOUMA DOUDOU ET CIE | J13: VIEUX KOUBA | K13: 00175/2025 | L13: 4065495
... A42: 45965 | B42: INTERFACE USB/KNX | C42: 1 | D42: U | E42: 21176.47 | F42: =C42*E42 -> 21176.47 | G42: =F42*0.19 -> 4023.5293 | H42: =F42+G42 -> 25199.999 | I42: CEFA | J42: VIEUX KOUBA | K42: 00071/2026 | L42: 3165209
A43: 46054 | B43: DISTRIBUTEUR 5 VOIES D 16 1"-26/34 A VISSER | C43: 2 | D43: U | E43: 5411.67 | F43: =C43*E43 -> 10823.34 | G43: =F43*0.19 -> 2056.4346 | H43: =F43+G43 -> 12879.775 | I43: BENROKHROCH ABDESSAMAD ETS AGUATECH | J43: VIEUX KOUBA | K43: 0153/2026 | L43: OD
A44: 46054 | B44: DISTRIBUTEUR 6 VOIES D 16 1"-26/34 A VISSER | C44: 8 | D44: U | E44: 6454.04 | F44: =C44*E44 -> 51632.32 | G44: =F44*0.19 -> 9810.1408 | H44: =F44+G44 -> 61442.461 | I44: BENROKHROCH ABDESSAMAD ETS AGUATECH | J44: VIEUX KOUBA | K44: 0153/2026 | L44: OD
A45: 46054 | B45: DISTRIBUTEUR 6 VOIES D 16 3/4"-20/27 A VISSER | C45: 14 | D45: U | E45: 5777.31 | F45: =C45*E45 -> 80882.34 | G45: =F45*0.19 -> 15367.645 | H45: =F45+G45 -> 96249.985 | I45: BENROKHROCH ABDESSAMAD ETS AGUATECH | J45: VIEUX KOUBA | K45: 0153/2026 | L45: OD
A46: 46054 | B46: DISTRIBUTEUR 5 VOIES D 16 3/4"-20/27 A VISSER | C46: 7 | D46: U | E46: 4529.41 | F46: =C46*E46 -> 31705.87 | G46: =F46*0.19 -> 6024.1153 | H46: =F46+G46 -> 37729.985 | I46: BENROKHROCH ABDESSAMAD ETS AGUATECH | J46: VIEUX KOUBA | K46: 0153/2026 | L46: OD
A47: 46054 | B47: DISTRIBUTEUR 4 VOIES D 16 3/4"-20/27 A VISSER | C47: 15 | D47: U | E47: 3836.13 | F47: =C47*E47 -> 57541.95 | G47: =F47*0.19 -> 10932.971 | H47: =F47+G47 -> 68474.921 | I47: BENROKHROCH ABDESSAMAD ETS AGUATECH | J47: VIEUX KOUBA | K47: 0153/2026 | L47: OD
A48: 46054 | B48: DISTRIBUTEUR 3 VOIES D 16 3/4"-20/27 A VISSER | C48: 11 | D48: U | E48: 2897.89 | F48: =C48*E48 -> 31876.79 | G48: =F48*0.19 -> 6056.5901 | H48: =F48+G48 -> 37933.38 | I48: BENROKHROCH ABDESSAMAD ETS AGUATECH | J48: VIEUX KOUBA | K48: 0153/2026 | L48: OD
A49: 46054 | B49: TUBE MC PEX /AL/PEX ALIMENTAIRE D 16 CALORIFUGE BLUE | C49: 2000 | D49: U | E49: 155.29 | F49: =C49*E49 -> 310580 | G49: =F49*0.19 -> 59010.2 | H49: =F49+G49 -> 369590.2 | I49: BENROKHROCH ABDESSAMAD ETS AGUATECH | J49: VIEUX KOUBA | K49: 0153/2026 | L49: OD
A50: 46054 | B50: TUBE MC PEX /AL/PEX ALIMENTAIRE D 16 CALORIFUGE ROUGE | C50: 2000 | D50: U | E50: 155.29 | F50: =C50*E50 -> 310580 | G50: =F50*0.19 -> 59010.2 | H50: =F50+G50 -> 369590.2 | I50: BENROKHROCH ABDESSAMAD ETS AGUATECH | J50: VIEUX KOUBA | K50: 0153/2026 | L50: OD
A51: 46054 | B51: TUBE MC CHILAI PEX D 16 GAINE BLUE | C51: 2000 | D51: U | E51: 103.52 | F51: =C51*E51 -> 207040 | G51: =F51*0.19 -> 39337.6 | H51: =F51+G51 -> 246377.6 | I51: BENROKHROCH ABDESSAMAD ETS AGUATECH | J51: VIEUX KOUBA | K51: 0153/2026 | L51: OD
A52: 46054 | B52: TUBE MC CHILAI PEX D 16 GAINE ROUGE | C52: 1000 | D52: U | E52: 103.52 | F52: =C52*E52 -> 103520 | G52: =F52*0.19 -> 19668.8 | H52: =F52+G52 -> 123188.8 | I52: BENROKHROCH ABDESSAMAD ETS AGUATECH | J52: VIEUX KOUBA | K52: 0153/2026 | L52: OD
A53: 46054 | B53: TUBE SIMPLE D 32 PN-20 PPRC | C53: 250 | D53: U | E53: 162.98 | F53: =C53*E53 -> 40745 | G53: =F53*0.19 -> 7741.55 | H53: =F53+G53 -> 48486.55 | I53: BENROKHROCH ABDESSAMAD ETS AGUATECH | J53: VIEUX KOUBA | K53: 0153/2026 | L53: OD
A54: 46054 | B54: COUDE 90° D32 PPRC | C54: 100 | D54: U | E54: 25.16 | F54: =C54*E54 -> 2516 | G54: =F54*0.19 -> 478.04 | H54: =F54+G54 -> 2994.04 | I54: BENROKHROCH ABDESSAMAD ETS AGUATECH | J54: VIEUX KOUBA | K54: 0153/2026 | L54: OD
... A78: 46054 | B78: TEFLON LIQUIDE BLEU 50 ML | C78: 8 | D78: U | E78: 554.62 | F78: =C78*E78 -> 4436.96 | G78: =F78*0.19 -> 843.0224 | H78: =F78+G78 -> 5279.9824 | I78: BENROKHROCH ABDESSAMAD ETS AGUATECH | J78: VIEUX KOUBA | K78: 0153/2026 | L78: OD
A79: 46041 | B79: SIKA WALL 10 PRIMER PL20 | C79: 20 | D79: PCS | E79: 4201.68 | F79: =C79*E79 -> 84033.6 | G79: =F79*0.19 -> 15966.384 | H79: =F79+G79 -> 99999.984 | I79: BACHA FARID | J79: VIEUX KOUBA | K79: 0024/2026 | L79: 4065452
A80: 46041 | B80: POINTE DE PARIS 100 | C80: 10 | D80: KG | E80: 159.66 | F80: =C80*E80 -> 1596.6 | G80: =F80*0.19 -> 303.354 | H80: =F80+G80 -> 1899.954 | I80: BACHA FARID | J80: VIEUX KOUBA | K80: 0024/2026 | L80: 4065452
A81: 46043 | B81: SDS PLUS P4/8*210 MM | C81: 20 | D81: U | E81: 1325.22 | F81: =C81*E81 -> 26504.4 | G81: =F81*0.19 -> 5035.836 | H81: =F81+G81 -> 31540.236 | I81: EURL HADDAD EQUIPMENT PROFFESIONNEL | J81: VIEUX KOUBA | K81: 00025/2026 | L81: 4065468
A82: 46043 | B82: SDS PLUS P4/8*210 MM | C82: 10 | D82: U | E82: 1562.93 | F82: =C82*E82 -> 15629.3 | G82: =F82*0.19 -> 2969.567 | H82: =F82+G82 -> 18598.867 | I82: EURL HADDAD EQUIPMENT PROFFESIONNEL | J82: VIEUX KOUBA | K82: 00025/2026 | L82: 4065468
A83: 46043 | B83: SDS PLUS P4/8*210 MM | C83: 10 | D83: U | E83: 1877.16 | F83: =C83*E83 -> 18771.6 | G83: =F83*0.19 -> 3566.604 | H83: =F83+G83 -> 22338.204 | I83: EURL HADDAD EQUIPMENT PROFFESIONNEL | J83: VIEUX KOUBA | K83: 00025/2026 | L83: 4065468
A84: 46043 | B84: SDS FORET MARTEAU 14*200 MM | C84: 10 | D84: U | E84: 1540.15 | F84: =C84*E84 -> 15401.5 | G84: =F84*0.19 -> 2926.285 | H84: =F84+G84 -> 18327.785 | I84: EURL HADDAD EQUIPMENT PROFFESIONNEL | J84: VIEUX KOUBA | K84: 00025/2026 | L84: 4065468
A85: 46048 | B85: TUBE PVC D 125 PNO6 COLLER EP3,2 | C85: 90 | D85: U | E85: 477.6 | F85: =C85*E85 -> 42984 | G85: =F85*0.19 -> 8166.96 | H85: =F85+G85 -> 51150.96 | I85: BENROKHROCH ABDESSAMAD ETS AGUATECH | J85: VIEUX KOUBA | K85: 0102/2026 | L85: OD
A86: 46048 | B86: Y REDUIT PVC D110*50 | C86: 22 | D86: U | E86: 172.85 | F86: =C86*E86 -> 3802.7 | G86: =F86*0.19 -> 722.513 | H86: =F86+G86 -> 4525.213 | I86: BENROKHROCH ABDESSAMAD ETS AGUATECH | J86: VIEUX KOUBA | K86: 0102/2026 | L86: OD
A87: 46048 | B87: Y REDUIT PVC D110*40 | C87: 120 | D87: U | E87: 162.68 | F87: =C87*E87 -> 19521.6 | G87: =F87*0.19 -> 3709.104 | H87: =F87+G87 -> 23230.704 | I87: BENROKHROCH ABDESSAMAD ETS AGUATECH | J87: VIEUX KOUBA | K87: 0102/2026 | L87: OD
A88: 46048 | B88: Y REDUIT PVC D80*40 | C88: 12 | D88: U | E88: 121.09 | F88: =C88*E88 -> 1453.08 | G88: =F88*0.19 -> 276.0852 | H88: =F88+G88 -> 1729.1652 | I88: BENROKHROCH ABDESSAMAD ETS AGUATECH | J88: VIEUX KOUBA | K88: 0102/2026 | L88: OD
A89: 46048 | B89: Y REDUIT PVC D110 | C89: 12 | D89: U | E89: 233.86 | F89: =C89*E89 -> 2806.32 | G89: =F89*0.19 -> 533.2008 | H89: =F89+G89 -> 3339.5208 | I89: BENROKHROCH ABDESSAMAD ETS AGUATECH | J89: VIEUX KOUBA | K89: 0102/2026 | L89: OD
A90: 46048 | B90: CHEVILLE PLASTIAUE N10 | C90: 600 | D90: U | E90: 2.77 | F90: =C90*E90 -> 1662 | G90: =F90*0.19 -> 315.78 | H90: =F90+G90 -> 1977.78 | I90: BENROKHROCH ABDESSAMAD ETS AGUATECH | J90: VIEUX KOUBA | K90: 0102/2026 | L90: OD
A91: 46048 | B91: TUBE PVC D10 PN06 A COLLER EP 2,0 | C91: 444 | D91: U | E91: 344.53 | F91: =C91*E91 -> 152971.32 | G91: =F91*0.19 -> 29064.551 | H91: =F91+G91 -> 182035.87 | I91: BENROKHROCH ABDESSAMAD ETS AGUATECH | J91: VIEUX KOUBA | K91: 0102/2026 | L91: OD
...

Sheet DJNANE SFARI
A1: DATE | B1: ARTICLE | C1: QUANTITE | D1: UNITE | E1: PRIX UNITAIRE | F1: MONTANT TOTAL HT | G1: TVA 19% | H1: TOTAL TTC | I1: FOURNISSEUR | J1: PROJET | K1: N FACTURE | L1: NUM CHEQUE
A2: 46027 | B2: PVC TUBE 500 PN 6 GHARDAIA | C2: 5 | D2: U | E2: 45400 | F2: =C2*E2 -> 227000 | G2: =F2*0.19 -> 43130 | H2: =F2+G2 -> 270130 | I2: SARL GREEN LANDIN | J2: DJENANE SFARI | K2: 266/2026 | L2: 4065511
A3: 46068 | B3: BETON CLASSE C 25/30 350 KG | C3: 170 | D3: M3 | E3: 7700 | F3: =C3*E3 -> 1309000 | G3: =F3*0.19 -> 248710 | H3: =F3+G3 -> 1557710 | I3: zouaoui smail | J3: DJENANE SFARI | K3: 015/26 | L3: 4065501
A4: 46075 | B4: PLAQYE D6 4/2 15/15 | C4: 100 | D4: U | E4: 3200 | F4: =C4*E4 -> 320000 | G4: =F4*0.19 -> 60800 | H4: =F4+G4 -> 380800 | I4: SARL SK METAL | J4: DJENANE SFARI | K4: 21/2026 | L4: 4065520
A5: 46079 | B5: REBAR 25,00*12000*RD500W | C5: 62000 | D5: KG | E5: 97.48 | F5: =C5*E5 -> 6043760 | G5: =F5*0.19 -> 1148314.4 | H5: =F5+G5 -> 7192074.4 | I5: SARL LEADER METAL | J5: DJENANE SFARI | K5: 00072/26 | L5: 4065525
A6: 46110 | B6: BETON CLASSE C 25/30 350 KG | C6: 716 | D6: M3 | E6: 7700 | F6: =C6*E6 -> 5513200 | G6: =F6*0.19 -> 1047508 | H6: =F6+G6 -> 6560708 | I6: zouaoui smail | J6: DJENANE SFARI | K6: 034/26 | L6: 4065422
A7: 46111 | B7: LAICA ETALONAGE/ MISE A JOUR DE CALIBRATION D APPAREIL TOPORAPHIQUE LEICA TS07 | C7: 1 | D7: U | E7: 25000 | F7: =C7*E7 -> 25000 | G7: =F7*0.19 -> 4750 | H7: =F7+G7 -> 29750 | I7: TERRAIN MATRICS HUB SARL | J7: DJENANE SFARI | K7: 34/2026 | L7: 4065424
A8: 46125 | B8: BETON CLASSE C 25/30 350 KG | C8: 512.5 | D8: M3 | E8: 7700 | F8: =C8*E8 -> 3946250 | G8: =F8*0.19 -> 749787.5 | H8: =F8+G8 -> 4696037.5 | I8: zouaoui smail | J8: DJENANE SFARI | K8: 036/26 | L8: 4065438
A9: 46132 | B9: BETON CLASSE C 25/30 350 KG | C9: 593 | D9: M3 | E9: 7700 | F9: =C9*E9 -> 4566100 | G9: =F9*0.19 -> 867559 | H9: =F9+G9 -> 5433659 | I9: zouaoui smail | J9: DJENANE SFARI | K9: 037/26 | L9: 4065447
A10: 46132 | B10: BETON CLASSE C25/30 350KG | C10: 593 | D10: M3 | E10: 7700 | F10: =C10*E10 -> 4566100 | G10: =F10*0.19 -> 867559 | H10: =F10+G10 -> 5433659 | I10: zouaoui smail | J10: DJENANE SFARI | K10: 037/26 | L10: 4065447
A11: 46133 | B11: FIL D ACIER 1,10 MM | C11: 1000 | D11: KG | E11: 135 | F11: =C11*E11 -> 135000 | G11: =F11*0.19 -> 25650 | H11: =F11+G11 -> 160650 | I11: SARL IMAFIL | J11: DJENANE SFARI | K11: 080/26 | L11: 4065057
A12: 46133 | B12: REBAR 25,00*12000*RD500W | C12: 62030 | D12: KG | E12: 100 | F12: =C12*E12 -> 6203000 | G12: =F12*0.19 -> 1178570 | H12: =F12+G12 -> 7381570 | I12: SARL LEADER METAL | J12: DJENANE SFARI | K12: 00126/26 | L12: 4065448
A13: 46133 | B13: TARNSPORT | C13: 2 | D13: U | E13: 14285.71 | F13: =C13*E13 -> 28571.42 | G13: =F13*0.19 -> 5428.5698 | H13: =F13+G13 -> 33999.99 | I13: SARL LEADER METAL | J13: DJENANE SFARI | K13: 00126/26 | L13: 4065448
... A27: 46186 | B27: ROND A BETON 20 | C27: 19.4 | D27: QX | E27: 10043 | F27: =C27*E27 -> 194834.2 | G27: =F27*0.19 -> 37018.498 | H27: =F27+G27 -> 231852.7 | I27: SARL GALAXY METAL | J27: DJENANE SFARI | K27: 00678/2026 | L27: 4065124
A28: 46195 | B28: TRANSPORT | C28: 1 | E28: 8403.36 | F28: =C28*E28 -> 8403.36 | G28: =F28*0.19 -> 1596.6384 | H28: =F28+G28 -> 9999.9984 | I28: SARL LEADER METAL | J28: DJENANE SFARI | K28: 00174/26 | L28: 4065159
A29: 46195 | B29: FER ROND A BETON 25 | C29: 40480 | D29: KG | E29: 100 | F29: =C29*E29 -> 4048000 | G29: =F29*0.19 -> 769120 | H29: =F29+G29 -> 4817120 | I29: SARL LEADER METAL | J29: DJENANE SFARI | K29: 00174/26 | L29: 4065159
A30: 46195 | B30: ROND A BETON 12 TOYASLI | C30: 4060 | E30: 98.739458 | F30: =C30*E30 -> 400882.2 | G30: =F30*0.19 -> 76167.618 | H30: =F30+G30 -> 477049.82 | I30: SARL LEADER METAL | J30: DJENANE SFARI | K30: 00187/26 | L30: 4065173
A31: 46195 | B31: ROND A BETON 25 TOYASLI | C31: 20160 | D31: KG | E31: 100 | F31: =C31*E31 -> 2016000 | G31: =F31*0.19 -> 383040 | H31: =F31+G31 -> 2399040 | I31: SARL LEADER METAL | J31: DJENANE SFARI | K31: 00187/26 | L31: 4065173
A32: 46125 | B32: FER ROND A BETON DIM 25 TOYASLI | C32: 60900 | D32: KG | E32: 100 | F32: =C32*E32 -> 6090000 | G32: =F32*0.19 -> 1157100 | H32: =F32+G32 -> 7247100 | I32: SARL LEADER METAL | J32: DJENANE SFARI | K32: 00121/26 | L32: 4065437
A33: 46125 | B33: TRANSPORT | C33: 2 | D33: KG | E33: 14285.714 | F33: =C33*E33 -> 28571.429 | G33: =F33*0.19 -> 5428.5714 | H33: =F33+G33 -> 34000 | I33: SARL LEADER METAL | J33: DJENANE SFARI | K33: 00121/26 | L33: 4065437
A34: 46210 | B34: ACCESOIRE PLOMBERIE POUR INSTALLATIO CITERNE D EAU PROJET 435 LOGMNET | C34: 1 | D34: FORFAIT | E34: 13490 | F34: =C34*E34 -> 13490 | G34: =F34*0.19 -> 2563.1 | H34: =F34+G34 -> 16053.1 | I34: TALAKHIR NADJIB | J34: DJENANE SFARI | K34: NOT EXIST
A35: 46195 | B35: ROND A BETON 25 | C35: 122 | D35: QX | E35: 10000 | F35: =C35*E35 -> 1220000 | G35: =F35*0.19 -> 231800 | H35: =F35+G35 -> 1451800 | I35: SARL GALAXY METAL | J35: DJENANE SFARI | K35: 00771/2026 | L35: 4065158
A36: 46195 | B36: TRANSPORT | C36: 1 | D36: PCS | E36: 10084.03 | F36: =C36*E36 -> 10084.03 | G36: =F36*0.19 -> 1915.9657 | H36: =F36+G36 -> 11999.996 | I36: SARL GALAXY METAL | J36: DJENANE SFARI | K36: 00771/2026 | L36: 4065158
A37: 46195 | B37: BETON CLASSE C25/350KG | C37: 1071.5 | D37: M3 | E37: 7700 | F37: =C37*E37 -> 8250550 | G37: =F37*0.19 -> 1567604.5 | H37: =F37+G37 -> 9818154.5 | I37: zouaoui smail | J37: DJENANE SFARI | K37: 075/26 | L37: 4065172
A38: 46216 | B38: ROND A BETON 12 | C38: 6100 | D38: KG | E38: 98.7396 | F38: =C38*E38 -> 602311.56 | G38: =F38*0.19 -> 114439.2 | H38: =F38+G38 -> 716750.76 | I38: SARL LEADER METAL | J38: DJENANE SFARI | K38: 00197/26 | L38: 4065189
A39: 46216 | B39: TRANSPORT | C39: 1 | D39: PCS | E39: 10084.03 | F39: =C39*E39 -> 10084.03 | G39: =F39*0.19 -> 1915.9657 | H39: =F39+G39 -> 11999.996 | I39: SARL LEADER METAL | J39: DJENANE SFARI | K39: 00197/26 | L39: 4065189
A40: 46232 | B40: GEOTEXTILE NON TISSE 150G/PP2,5M*40M | C40: 300 | D40: M2 | E40: 150 | F40: =C40*E40 -> 45000 | G40: =F40*0.19 -> 8550 | H40: =F40+G40 -> 53550 | I40: SARL OROMAX | J40: DJENANE SFARI | K40: 122/2026 | L40: 4065228
A41: 46214 | B41: FIL RECUIT O 0,10 MM | C41: 1009 | D41: KG | E41: 135 | F41: =C41*E41 -> 136215 | G41: =F41*0.19 -> 25880.85 | H41: =F41+G41 -> 162095.85 | I41: SARL IMAFIL | J41: DJENANE SFARI | K41: 144/26 | L41: 4065207
A42: 46225 | B42: WATER STOP 30MM*25 M | C42: 3 | D42: PCS | E42: 49450 | F42: =C42*E42 -> 148350 | G42: =F42*0.19 -> 28186.5 | H42: =F42+G42 -> 176536.5 | I42: EURL INNOFAR TRADING | J42: DJENANE SFARI | K42: 005151/26 | L42: 4065215
A43: 46214 | B43: CABLE 4*6MM SOUPLE | C43: 100 | D43: M | E43: 770 | F43: =C43*E43 -> 77000 | G43: =F43*0.19 -> 14630 | H43: =F43+G43 -> 91630 | I43: SARL SONELTECH ELECTRIC | J43: DJENANE SFARI | K43: 145/2026 | L43: 4065206
A44: 46214 | B44: PRISE DE FORCE MURALE FEMAL 4*16 TURK | C44: 5 | D44: PCS | E44: 1400 | F44: =C44*E44 -> 7000 | G44: =F44*0.19 -> 1330 | H44: =F44+G44 -> 8330 | I44: SARL SONELTECH ELECTRIC | J44: DJENANE SFARI | K44: 145/2026 | L44: 4065206
A45: 46214 | B45: PRISE DE FORCE MURALE MALE 4*16 TURK | C45: 5 | D45: PCS | E45: 786.6 | F45: =C45*E45 -> 3933 | G45: =F45*0.19 -> 747.27 | H45: =F45+G45 -> 4680.27 | I45: SARL SONELTECH ELECTRIC | J45: DJENANE SFARI | K45: 145/2026 | L45: 4065206
A46: 46214 | B46: A9K IK60N 4P 40A DISJONCTER MINIATU SCHEIDER | C46: 1 | D46: PCS | E46: 3950 | F46: =C46*E46 -> 3950 | G46: =F46*0.19 -> 750.5 | H46: =F46+G46 -> 4700.5 | I46: SARL SONELTECH ELECTRIC | J46: DJENANE SFARI | K46: 145/2026 | L46: 4065206
... A53: 46237 | B53: TRANSPORT | C53: 1 | D53: PCS | E53: 2000 | F53: =C53*E53 -> 2000 | G53: =F53*0.19 -> 380 | H53: =F53+G53 -> 2380 | I53: SOGEDIM | J53: DJENANE SFARI | K53: 00639/26 | L53: 4065236
A54: TOTAL | F54: =SUM(F2:F53) -> 94964845 | G54: =SUM(G2:G53) -> 18043321 | H54: =SUM(H2:H53) -> 1.1300817e+08

Sheet RESUME GLOBAL
A1: PROJET | B1: MONTANT HT | C1: MONTANT TVA | D1: MONTANT TTC
A2: VIEUX KOUBA | B2: =SUMIF(GLOBAL!$J:$J,A2,GLOBAL!$F:$F) -> 18885000 | C2: =SUMIF(GLOBAL!$J:$J,A2,GLOBAL!$G:$G) -> 3588150 | D2: =SUMIF(GLOBAL!$J:$J,A2,GLOBAL!$H:$H) -> 22473150
A3: DJENANE SFARI | B3: =SUMIF(GLOBAL!$J:$J,A3,GLOBAL!$F:$F) -> 94964845 | C3: =SUMIF(GLOBAL!$J:$J,A3,GLOBAL!$G:$G) -> 18043321 | D3: =SUMIF(GLOBAL!$J:$J,A3,GLOBAL!$H:$H) -> 1.1300817e+08
A4: TOTAL | B4: =SUM(B2:B3) -> 1.1384984e+08 | C4: =SUM(C2:C3) -> 21631470 | D4: =SUM(D2:D3) -> 1.3548132e+08
